<?xml version="1.0"?>
<robot xmlns:xacro="http://www.ros.org/wiki/xacro">

<xacro:include filename="inertial_macros.xacro" />

<material name="white">
    <color rgba="1 1 1 1"/>
</material>

<material name="orange">
    <color rgba="1 0.3 0.1 1"/>
</material>

<material name="blue">
    <color rgba="0.2 0.2 1 1"/>
</material>

<material name="black">
    <color rgba="0 0 0 1"/>
</material>

<!--base link-->

<link name="base_link">
</link>

<!-- BASE_FOOTPRINT LINK -->

    <joint name="base_footprint_joint" type="fixed">
        <parent link="base_link"/>
        <child link="base_footprint"/>
        <origin xyz="0 0 0" rpy="0 0 0"/>
    </joint>

    <link name="base_footprint">
    </link>

<!--chasis link-->

<joint name="chassis_joint" type="fixed">
    <parent link="base_link"/>
    <child link="chassis"/>
    <origin xyz="-0.1 0 0"/>
</joint>

<link name="chassis">
    <visual>
        <origin xyz="0.15 0 0.075" rpy="0 0 0"/>  //shift origin half length forward and half height to allign in between two wheels
        <geometry>
            <box size="0.3 0.3 0.15"/>
        </geometry>
        <material name="white"/>
    </visual>
        <collision>
        <origin xyz="0.15 0 0.075" rpy="0 0 0"/>
        <geometry>
            <box size="0.3 0.3 0.15"/>
        </geometry>
    </collision>
        <xacro:inertial_box mass="0.5" x="0.3" y="0.3" z="0.15">
        <origin xyz="0.15 0 0.075" rpy="0 0 0"/>
    </xacro:inertial_box>
</link>
 
<gazebo reference="chassis">
    <material>Gazebo/White</material>
</gazebo>

<!--left wheel link-->

<joint name="left_wheel_joint" type="continuous">
    <parent link="base_link"/>
    <child link="left_wheel"/>
    <origin xyz="0.06 0.175 0.015" rpy="-${pi/2} 0 0"/>     //-pi/2 =yaw, roll and pitch=0
    <axis xyz="0 0 1"/>                              //move forward
</joint>

<link name="left_wheel">
    <visual>
        <geometry>
            <cylinder length="0.04" radius="0.052" />
        </geometry>
        <material name="blue"/>
    </visual>
        <collision>
        <geometry>
            <cylinder length="0.04" radius="0.052" />
        </geometry>
        <material name="blue"/>
    </collision>
        <xacro:inertial_cylinder mass="0.1" length="0.05" radius="0.052">
        <origin xyz="0 0 0" rpy="0 0 0"/>
    </xacro:inertial_cylinder>
</link>

<gazebo reference="left_wheel">
    <material>Gazebo/Blue</material>
</gazebo>

<!--right wheel link-->

<joint name="right_wheel_joint" type="continuous">
    <parent link="base_link"/>
    <child link="right_wheel"/>
    <origin xyz="0.06 -0.175 0.015" rpy="${pi/2} 0 0"/>
    <axis xyz="0 0 -1"/>
</joint>

<link name="right_wheel">
    <visual>
        <geometry>
            <cylinder length="0.04" radius="0.052" />
        </geometry>
        <material name="blue"/>
    </visual>
        <collision>
        <geometry>
            <cylinder length="0.04" radius="0.052" />
        </geometry>
        <material name="blue"/>
    </collision>
        <xacro:inertial_cylinder mass="0.1" length="0.05" radius="0.052">
        <origin xyz="0 0 0" rpy="0 0 0"/>
    </xacro:inertial_cylinder>
</link>



<gazebo reference="right_wheel">
    <material>Gazebo/Blue</material>
</gazebo>


<!--caster wheel1 link-->      

<joint name="caster_wheel1_joint" type="fixed">
    <parent link="chassis"/>
    <child link="caster_wheel1"/>
    <origin xyz="0.26 -0.11 0" rpy="0 0 0"/>
</joint>

<link name="caster_wheel1">
    <visual>
        <geometry>
            <sphere radius="0.03" />
        </geometry>
        <material name="black"/>
    </visual>
        <collision>
        <geometry>
            <sphere radius="0.03" />
        </geometry>
        <material name="black"/>
    </collision>
        <xacro:inertial_sphere mass="0.1" radius="0.03">
        <origin xyz="0 0 0" rpy="0 0 0"/>
    </xacro:inertial_sphere>
</link>



<gazebo reference="caster_wheel1">
    <material>Gazebo/Black</material>
    <mu1 value="0.001"/>
    <mu2 value="0.001"/>
</gazebo>

<!--caster wheel2 link-->

<joint name="caster_wheel2_joint" type="fixed">
    <parent link="chassis"/>
    <child link="caster_wheel2"/>
    <origin xyz="0.26 0.11 0" rpy="0 0 0"/>
</joint>

<link name="caster_wheel2">
    <visual>
        <geometry>
            <sphere radius="0.03" />
        </geometry>
        <material name="black"/>
    </visual>
        <collision>
        <geometry>
            <sphere radius="0.03" />
        </geometry>
        <material name="black"/>
    </collision>
        <xacro:inertial_sphere mass="0.1" radius="0.03">
        <origin xyz="0 0 0" rpy="0 0 0"/>
    </xacro:inertial_sphere>
</link>


<gazebo reference="caster_wheel2">
    <material>Gazebo/Black</material>
        <mu1 value="0.001"/>
    <mu2 value="0.001"/>
</gazebo>



<!--caster wheel3 link-->

<joint name="caster_wheel3_joint" type="fixed">
    <parent link="chassis"/>
    <child link="caster_wheel3"/>
    <origin xyz="0.05 0.11 0" rpy="0 0 0"/>
</joint>

<link name="caster_wheel3">
    <visual>
        <geometry>
            <sphere radius="0.03" />
        </geometry>
        <material name="black"/>
    </visual>
        <collision>
        <geometry>
            <sphere radius="0.03" />
        </geometry>
        <material name="black"/>
    </collision>
        <xacro:inertial_sphere mass="0.1" radius="0.03">
        <origin xyz="0 0 0" rpy="0 0 0"/>
    </xacro:inertial_sphere>
</link>



<gazebo reference="caster_wheel3">
    <material>Gazebo/Black</material>
        <mu1 value="0.001"/>
    <mu2 value="0.001"/>
</gazebo>



<!--caster wheel4 link-->

<joint name="caster_wheel4_joint" type="fixed">
    <parent link="chassis"/>
    <child link="caster_wheel4"/>
    <origin xyz="0.05 -0.11 0" rpy="0 0 0"/>
</joint>

<link name="caster_wheel4">
    <visual>
        <geometry>
            <sphere radius="0.035" />
        </geometry>
        <material name="black"/>
    </visual>
        <collision>
        <geometry>
            <sphere radius="0.035" />
        </geometry>
        <material name="black"/>
    </collision>
        <xacro:inertial_sphere mass="0.1" radius="0.035">
        <origin xyz="0 0 0" rpy="0 0 0"/>
    </xacro:inertial_sphere>
</link>



<gazebo reference="caster_wheel4">
    <material>Gazebo/Black</material>
        <mu1 value="0.001"/>
    <mu2 value="0.001"/>
</gazebo>



</robot>